Workbook

Sheet Final_Cleaned_Data_V2
B1: (Clean this out prior to datathon) | J1: 1 | L1: 2 | M1: 3 | O1: 4 | P1: 5 | Q1: 6 | R1: 7 | S1: 8 | T1: 9
A2: Unnamed: 0 | B2: text | C2: url | D2: name | E2: department | F2: text_len | G2: too_long_flag | H2: Volunteer ID | I2: Progress | J2: Text Type | L2: Incident Mentioned | M2: Incident Type | O2: Difficulty to extract incident type | P2: Officers Perpetrating Incident | Q2: Officer Gender | R2: Officer Race | S2: Complainant Gender | T2: Complainant Race | U2: Location Found | V2: Location (if found) | W2: Difficulty of Finding Location | X2: Date (leave blank if unknown) | Y2: Time
A3: 82 | B3: UNITED STATES DISTRICT COURT DISTRICT OF MINNESOTA Luis Daniel Garcia, Plaintiff, vs. Blayne Lehner, in his individual capacity as an officer of the City of Minneapolis, and the City of Minneapolis, Defendants. FILE NO. 15-cv-3214 (SRN/HB) ORDER Pursuant to the stipulation of the Plaintiff and the City of Minneapolis [Doc. No. 28], all claims against the City of Minneapolis are hereby dismissed with prejudice and without costs to either party. Dated: July 20, 2016 s/Susan Richard Nelson SUSAN RICHARD NELSON United States District Judge CASE 0:15-cv-03214-SRN-HB Document 29 Filed 07/20/16 Page 1 of 1 | C3: ['https://d3n8a8pro7vhmx.cloudfront.net/cuapb/pages/270/attachments/original/1614138451/Document_29_Order_of_Dismissal.pdf?1614138451'] | D3: ['Blayne Lehner, badge #4073'] | E3: ['Department:Minneapolis Police Department'] | F3: 698 | K3: =IF(Final_Cleaned_Data_V2!J3="Other", "Please specify here", "") | N3: =IF(Final_Cleaned_Data_V2!M3="Other", "Please specify here", "")
A4: 83 | B4: Too_Long:Over 20 Pages OPCR Case #13-069Lel Lee PANEL RECOMMENDATION Page 2 of 4 Allegations 2. Inappropriate Language: That Officer Golgart used inappropriate language "You're an alcoholic." OPCR Case #13-069Lel Lee PANEL RECOMMENDATION Page 4 of 4 Allegation #2: Inappropriate Language Supportive Findings: YES NO REMAND SPLIT This allegation has merit. This allegation does not have merit. Remand to investigation for additional information. There is no majority vote. The panel unanimously finds there is sufficient evidence to find merit in this allegation. DH | C4: ['https://d3n8a8pro7vhmx.cloudfront.net/cuapb/pages/270/attachments/original/1581994153/OPCR_13-069_Part_1.pdf?1581994153'] | D4: ['James Golgart, Jr., badge #2317'] | E4: ['Department:Minneapolis Police Department'] | F4: 711 | G4: TRUE | K4: =IF(Final_Cleaned_Data_V2!J4="Other", "Please specify here", "") | N4: =IF(Final_Cleaned_Data_V2!M4="Other", "Please specify here", "")
A5: 84 | B5: PUBLIC INFORMATION - EMPLOYEE SUMMARY SAINT PAUL POLICE DEPARTMENT INTERNAL AFFAIRS UNIT Employee Name: HALLSTROM, KURTIS W. Employee ID: 253400 From: January 01, 1900 to October 05, 2022 IA Number: 00-0116 STATUS: Completed Complainant: Diperna, Nancy IA Number: 01-0506 STATUS: Completed Complainant: Attorney, City Allegation Final Disposition Discipline? Allegations Discipline Comments Improper Procedure Sustained Oral Reprim Oral Reprimand IA Number: 03-0419 STATUS: Completed Complainant: Pye, Gregory IA Number: 17-0709 STATUS: Completed Complainant: Thomas, Jacob IA Number: 22-0809 STATUS: Completed Complainant: Commander Sean Lohse-Johnson Printed: 10/5/2022 9:03:13 AM [by: Drake, Lisa (CI-StPaul) (Chiefs Office/Internal A] Page 1 of 1 | C5: ['https://assets.nationbuilder.com/cuapb/pages/270/attachments/original/1667360765/Hallstrom_-_Public_IA.pdf?1667360765'] | D5: ['Kurtis W. Hallstrom, badge #253400'] | E5: ['Department:St. Paul Police Department'] | F5: 750 | K5: =IF(Final_Cleaned_Data_V2!J5="Other", "Please specify here", "") | N5: =IF(Final_Cleaned_Data_V2!M5="Other", "Please specify here", "")
A6: 85 | B6: 5 EXHIBIT A UNITED STATES DISTRICT COURT DISTRICT OF MINNESOTA Dennis Melvin Hill, Plaintiff, vs. The City of Minneapolis, Officer Matthew Kaminski, Officer Jason Schmitt, and John Doe Officers, Defendants. COURT FILE NO. 13-cv-705 PJS/SER JOINT STIPULATION TO DISMISS THE CITY OF MINNEAPOLIS AND THE COMPLAINT WITH PREJUDICE The City of Minneapolis and Plaintiff, acting by and through their undersigned attorneys of record, hereby stipulate that, pursuant to Fed. R. Civ. P. 41, the Court shall dismiss Plaintiff's Complaint in its entirety, with prejudice, and without costs to any party. CASE 0:13-cv-00705-PJS-SER Doc. 34 Filed 09/02/14 Page 1 of 2 CASE 0:13-cv-00705-PJS-SER Doc. 34 Filed 09/02/14 Page 2 of 2 | C6: ['https://d3n8a8pro7vhmx.cloudfront.net/cuapb/pages/270/attachments/original/1626031083/kaminski_dismissal.pdf?1626031083'] | D6: ['Jason Schmitt, badge #6374', 'Matthew R. Kaminski, badge #3615'] | E6: ['Department:Minneapolis Police Department'] | F6: 777 | K6: =IF(Final_Cleaned_Data_V2!J6="Other", "Please specify here", "") | N6: =IF(Final_Cleaned_Data_V2!M6="Other", "Please specify here", "")
A7: 86 | B7: NOTICE OF REMOVAL, EXHIBIT B CASE 0:13-cv-00705-PJS-SER Doc. 1-2 Filed 03/27/13 Page 1 of 8 NOTICE OF REMOVAL, EXHIBIT B CASE 0:13-cv-00705-PJS-SER Doc. 1-2 Filed 03/27/13 Page 2 of 8 NOTICE OF REMOVAL, EXHIBIT B CASE 0:13-cv-00705-PJS-SER Doc. 1-2 Filed 03/27/13 Page 3 of 8 NOTICE OF REMOVAL, EXHIBIT B CASE 0:13-cv-00705-PJS-SER Doc. 1-2 Filed 03/27/13 Page 4 of 8 NOTICE OF REMOVAL, EXHIBIT B CASE 0:13-cv-00705-PJS-SER Doc. 1-2 Filed 03/27/13 Page 5 of 8 NOTICE OF REMOVAL, EXHIBIT B CASE 0:13-cv-00705-PJS-SER Doc. 1-2 Filed 03/27/13 Page 6 of 8 NOTICE OF REMOVAL, EXHIBIT B CASE 0:13-cv-00705-PJS-SER Doc. 1-2 Filed 03/27/13 Page 7 of 8 NOTICE OF REMOVAL, EXHIBIT B CASE 0:13-cv-00705-PJS-SER Doc. 1-2 Filed 03/27/13 Page 8 of 8 | C7: ['https://d3n8a8pro7vhmx.cloudfront.net/cuapb/pages/270/attachments/original/1626030759/kaminski_complaint_.pdf?1626030759'] | D7: ['Jason Schmitt, badge #6374', 'Matthew R. Kaminski, badge #3615'] | E7: ['Department:Minneapolis Police Department'] | F7: 783 | K7: =IF(Final_Cleaned_Data_V2!J7="Other", "Please specify here", "") | N7: =IF(Final_Cleaned_Data_V2!M7="Other", "Please specify here", "")
A8: 87 | B8: UNITED STATES DISTRICT COURT DISTRICT OF MINNESOTA Madelyn R. Milton, Plaintiff, vs. City of Minneapolis, Defendant. Civ. No.: 15-1930 (RHK/TNL) ORDER OF DISMISSAL OF CITY OF MINNEAPOLIS The above-captioned matter came before the Court on the parties' Stipulation of Dismissal of City of Minneapolis (Doc. No. 16). Based upon the parties' Stipulation, IT IS ORDERED that all claims against Defendant City of Minneapolis are DISMISSED WITH PREJUDICE, without costs or fees to any party. LET JUDGMENT BE ENTERED ACCORDINGLY. Dated: October 14, 2015 s/Richard H. Kyle RICHARD H. KYLE United States District Judge CASE 0:15-cv-01930-RHK-TNL Document 17 Filed 10/14/15 Page 1 of 1 | C8: ['https://d3n8a8pro7vhmx.cloudfront.net/cuapb/pages/270/attachments/original/1614450573/Milton_v._Barze_Document_17_Order_of_Dismissal_City_of_Mpls.pdf?1614450573'] | D8: ['Tyrone Barze, badge #330'] | E8: ['Department:Minneapolis Police Department'] | F8: 794 | K8: =IF(Final_Cleaned_Data_V2!J8="Other", "Please specify here", "") | N8: =IF(Final_Cleaned_Data_V2!M8="Other", "Please specify here", "")
A9: 88 | B9: 27-CV-05-007993 Filed in District Court State of Minnesota 8/27/2020 1:57 PM STATE OF MINNESOTA DISTRICT COURT COUNTY OF HENNEPIN FOURTH JUDICIAL DISTRICT Joshua Doring, Case File N0: 27-CV-05-007993 Plaintiff, vs. Ofcer Michael Kennedy, et a1, Defendants. SATISFACTION OF JUDGMENT FULL SATISFACTION: I, Jason M. Hiveley, the undersigned judgment creditor's attorney, hereby certify that the judgment entered and docketed in the above named court in the above entitled action on December 6, 2005, in favor of the City of Champlin, James Johans and Michael Kennedy and against Joshua Doring in the amount of $2,822.46 is fully satisfied and the Court Administrator shall record the same. (Signatye/ofJidgir'zem Credito "" Attorney) Sworn and subscribed to before me this 2nd day of March, 2012. - - REBECCA J. EITREIM Notary Public | C9: ['https://assets.nationbuilder.com/cuapb/pages/270/attachments/original/1671380372/kennedy_judgement_27-CV-05-007993.pdf?1671380372'] | D9: ['Michael Kennedy, badge #3693'] | E9: ['Department:Minneapolis Police Department'] | F9: 830 | K9: =IF(Final_Cleaned_Data_V2!J9="Other", "Please specify here", "") | N9: =IF(Final_Cleaned_Data_V2!M9="Other", "Please specify here", "")
A10: 89 | B10: Ex-officer charged with theft from Scouts POST BULLETIN October 23, 2000 04:00 AM STILLWATER, Minn. -- Former Police Sgt. Davin Miller has been charged with theft for allegedly taking money from a scouting troop he led. The Washington County Attorney's office on Friday charged Miller, 41, of Hudson, Wis., of misappropriating more than $2,000 from Stillwater Police Explorer POST 521, which he supervised from 1992 until February 2000, when he resigned from the department. The charge carries a maximum penalty of five years in jail and a $10,000 fine. According to a report by the state auditor's office that was forwarded to the county attorney, the actual amount misappropriated could be more than $10,700. Miller was the lone signatory on the Explorer POST bank account for more than five years, during which the transactions singled out by the auditors occurred. | C10: ['https://assets.nationbuilder.com/cuapb/pages/1472/attachments/original/1670343760/Miller_Davin_Ex-officer_charged_with_theft_from_Scouts.pdf?1670343760'] | D10: ['Davin Miller, badge #None'] | E10: ['Department:Stillwater Police Department'] | F10: 880 | K10: =IF(Final_Cleaned_Data_V2!J10="Other", "Please specify here", "") | N10: =IF(Final_Cleaned_Data_V2!M10="Other", "Please specify here", "")
A11: 90 | B11: HOME MN NEWS Belle Plaine o cer suspected of DWI a er driving 96 mph BMTN STAFF • UPDATED: MAR 8, 2018 · ORIGINAL: NOV 21, 2012 State patrol of cial a Belle Plaine police of cer Bran Michael Paek wa topped b a tate trooper on Highwa 169 roughl 40 mile outhwet of the Twin Citie near Belle Plaine, at 2:26 a.m. Tueda after driving 96 mph zone, the Belle Plaine Herald report. He wa off-dut at the time, WCCO report. The 32-ear-old of cer wa given a breath tet that howed a .17 blood-alcohol content level, twice the legal limit, the newpaper report. He had a imilar violation in 2003, the newpaper a. No one with the Belle Plaine police commented for a tor on Fox 9: KMSP-TV Belle Plaine officer suspected of DWI after driving 96 mph - Bring Me ... https://bringmethenews.com/minnesota-news/belle-plaine-officer-suspe... 1 of 1 12/27/2022, 12:54 AM | C11: ['https://assets.nationbuilder.com/cuapb/pages/1472/attachments/original/1672124550/Pasek_3_Belle_Plaine_officer_suspected_of_DWI_after_driving_96_mph_-_Bring_Me_The_News.pdf?1672124550'] | D11: ['Bryan M. Pasek, badge #None'] | E11: ['Department:Belle Plaine Police Department'] | F11: 881 | K11: =IF(Final_Cleaned_Data_V2!J11="Other", "Please specify here", "") | N11: =IF(Final_Cleaned_Data_V2!M11="Other", "Please specify here", "")
A12: 91 | B12: UNITED STATES DISTRICT COURT District of Minnesota Madelyn R. Milton, JUDGMENT IN A CIVIL CASE Plaintiff, v. Case Number: 15-1930 (RHK/TNL) City of Minneapolis, Defendant(s). Jury Verdict. This action came before the Court for a trial by jury. The issues have been tried and the jury has rendered its verdict. X Decision by Court. This action came to trial or hearing before the Court. The issues have been tried or heard and a decision has been rendered. IT IS ORDERED AND ADJUDGED THAT: All claims against Defendant City of Minneapolis are DISMISSED WITH PREJUDICE, without costs or fees to any party. Date: 10/13/2015 RICHARD D. SLETTEN, CLERK s/M. Price (By) M. Price, Deputy Clerk CASE 0:15-cv-01930-RHK-TNL Document 18 Filed 10/14/15 Page 1 of 1 | C12: ['https://d3n8a8pro7vhmx.cloudfront.net/cuapb/pages/270/attachments/original/1614450707/Milton_v._Barze_Document_18_Judgment.pdf?1614450707'] | D12: ['Tyrone Barze, badge #330'] | E12: ['Department:Minneapolis Police Department'] | F12: 881 | K12: =IF(Final_Cleaned_Data_V2!J12="Other", "Please specify here", "") | N12: =IF(Final_Cleaned_Data_V2!M12="Other", "Please specify here", "")
A13: 92 | B13: UNITED STATES DISTRICT COURT District of Minnesota Jon Gauthier, JUDGMENT IN A CIVIL CASE Plaintiff, v. Case Number: 15-cv-3068 (RHK/KMM) City of Minneapolis and Jordan Davis, Defendant(s). Jury Verdict. This action came before the Court for a trial by jury. The issues have been tried and the jury has rendered its verdict. X Decision by Court. This action came to trial or hearing before the Court. The issues have been tried or heard and a decision has been rendered. IT IS ORDERED AND ADJUDGED THAT: all claims against Defendant City of Minneapolis are DISMISSED WITH PREJUDICE and without costs or fees to any party Date: 12/28/2016 RICHARD D. SLETTEN, CLERK s/K. Krulas (By) K. Krulas, Deputy Clerk CASE 0:15-cv-03068-RHK-KMM Document 34 Filed 12/29/16 Page 1 of 1 | C13: ['https://d3n8a8pro7vhmx.cloudfront.net/cuapb/pages/270/attachments/original/1614974721/2016JonGauthierJudgment.pdf?1614974721'] | D13: ['Jordan Davis, badge #1434'] | E13: ['Department:Minneapolis Police Department'] | F13: 890 | K13: =IF(Final_Cleaned_Data_V2!J13="Other", "Please specify here", "") | N13: =IF(Final_Cleaned_Data_V2!M13="Other", "Please specify here", "")
A14: 93 | B14: Minneapolis Police Department Discipline Worksheet Sgt. Shannon Barnette, #0268 Employee's Name and ID Number 5/25/2017 Date of Incident Discipline Panel Recommendation OPCR 17-10527 Administrative Case Number Policy Number Policy Description Category Disposition 5-105 (A)(4) Professional Code of Conduct Merit 4-602 Report Writing Merit Deputy Chief of Professional Standards Date 13.43 - Personnel Data 1' 14' sc;c:' " 1332747 Minneapolis Police Department Discipline Worksheet Office of the Chief of Police Policy Number Policy Description Category Disposition 5-105 (A)(4) Professional Code of Conduct B Merit 4-602 Report Writing B Merit Final Disposition 5-105 (A)(4) Professional Code of Conduct, Sustained - B 4-602 Report Writing, Sustained - B Letter of Reprimand Chief of Police MP-1408 (Revised 12/15) 2 Date 1332748 1332749 1332750 | C14: ['https://assets.nationbuilder.com/cuapb/pages/1509/attachments/original/1753851699/17-10527_Shannon_Barnette-Discipline_Memo.pdf?1753851699'] | D14: ['Shannon L. Barnette, badge #268'] | E14: ['Department:Minneapolis Police Department'] | F14: 893 | K14: =IF(Final_Cleaned_Data_V2!J14="Other", "Please specify here", "") | N14: =IF(Final_Cleaned_Data_V2!M14="Other", "Please specify here", "")
A15: 94 | B15: Skip to content Offender Information Demographic Information** MNDOC Offender ID: 243907 Name: Aaron Joseph Heuer Birth Date: 10/11/1983 Current Status: Incarcerated as of 05/08/2014. Currently at a non-DOC facility. Sentence Date: 05/08/2014 Anticipated Release Date: 07/23/2035 Expiration Date: Life Caseworker: Abby Domagalski 651-779-2754 Current Offense Information Highest Ranked Offense: Criminal Sexual Conduct Court File Number(s): Otter Tail - 56-CR-13-2467 Otter Tail - 56-CR-13-1927 Mille Lacs - 48-CR-14-524 Other Links Go to MN Courts website (https://pa.courts.state.mn.us/default.aspx) to look up court case information (opens in a new window). Go to BCA website (https://chs.state.mn.us/) to look up criminal history information (opens in a new window). Offender Locator Details https://coms.doc.state.mn.us/publicviewer/OffenderDetails/Index/2439... 1 of 2 11/24/2022, 12:49 PM | C15: ['https://assets.nationbuilder.com/cuapb/pages/1472/attachments/original/1669315796/Aaron_Heuer_MN_DOC_Details.pdf?1669315796'] | D15: ['Aaron Heuer, badge #None'] | E15: ['Department:Mille Lacs County Sheriffs Office'] | F15: 895 | K15: =IF(Final_Cleaned_Data_V2!J15="Other", "Please specify here", "") | N15: =IF(Final_Cleaned_Data_V2!M15="Other", "Please specify here", "")
A16: 95 | B16: Skip to content Offender Information Demographic Information** MNDOC Offender ID: 237622 Name: William Allan Jacobs Birth Date: 07/11/1943 Current Status: Incarcerated as of 04/11/2012. Currently at MCF Lino Lakes (https://mn.gov /doc/facilities/lino-lakes/). Sentence Date: 04/09/2012 Anticipated Release Date: 03/04/2024 Expiration Date: Life Caseworker: Ryan Schill 651-717-6100 Current Offense Information Highest Ranked Offense: Criminal Sexual Conduct Court File Number(s): Hennepin - 27CR103626 Hennepin - 27CR103386 Other Links Go to MN Courts website (https://pa.courts.state.mn.us/default.aspx) to look up court case information (opens in a new window). Go to BCA website (https://chs.state.mn.us/) to look up criminal history information (opens in a new window). Offender Locator Details https://coms.doc.state.mn.us/publicviewer/OffenderDetails/Index/2376... 1 of 2 11/24/2022, 10:26 PM | C16: ['https://assets.nationbuilder.com/cuapb/pages/1472/attachments/original/1669350422/William_Jacobs_MN_DOC_Record.pdf?1669350422'] | D16: ['William Jacobs, badge #None'] | E16: ['Department:Minneapolis Park Police Department'] | F16: 898 | K16: =IF(Final_Cleaned_Data_V2!J16="Other", "Please specify here", "") | N16: =IF(Final_Cleaned_Data_V2!M16="Other", "Please specify here", "")
... A104: 183 | B104: Home >Legislative File 2021-00539 >RCA Legal Se lement: Workers' Compensa on claim of Andrew Hegseth (RCA-2021-00525) ORIGINATING DEPARTMENT Finance & Property Services To Commi ee(s) # Commi ee Name Mee ng Date 1 Policy & Government Oversight Commi ee May 12, 2021 LEAD STAFF: Emily Ann Colby PRESENTED BY: Emily Ann Colby Ac on Item(s) # File Type Subcategory Item Descrip on 1 Ac on Se lement Approving the Workers' Compensa on claim of Andrew Hegseth by payment of $90,000 to Mr. Hegseth and his a orneys Mesuer Law Firm and authorizing the City A orney's Office to execute any documents necessary to effectuate the se lement. Ward / Neighborhood / Address RCA-2021-00525 - Legal Settlement: Workers' Compensation claim of ... https://lims.minneapolismn.gov/RCA/7937 1 of 2 12/4/2021, 12:36 AM # Ward Neighborhood Address 1. Not Applicable Background Analysis Fomer MPD officer sustained work-related injuries. The par es reached a tenta ve se lement by payment of $90,000 from fund 06930-1450100-789401-145400. Risk Managment believes the se lement is in the best interests of the City and recommends approval by the Commi ee and the City Council. FISCAL NOTE • Legal Se lement: Workers' Compensa on claim of Andrew Hegseth - Fiscal Note RCA-2021-00525 - Legal Settlement: Workers' Compensation claim of ... https://lims.minneapolismn.gov/RCA/7937 2 of 2 12/4/2021, 12:36 AM | C104: ["https://d3n8a8pro7vhmx.cloudfront.net/cuapb/pages/1462/attachments/original/1638637588/RCA-2021-00525_-_Legal_Settlement_Workers'_Compensation_claim_of_Andrew_Hegseth.pdf?1638637588"] | D104: ['Andrew Hegseth, badge #2878'] | E104: ['Department:Minneapolis Police Department'] | F104: 1380 | K104: =IF(Final_Cleaned_Data_V2!J104="Other", "Please specify here", "") | N104: =IF(Final_Cleaned_Data_V2!M104="Other", "Please specify here", "")
A105: 184 | B105: Too_Long:Over 20 PagesCASE 0:15-cr-00247-PJS-SER Doc. 1 Filed 09/10/15 Page 1 of 23 CASE 0:15-cr-00247-PJS-SER Doc. 1 Filed 09/10/15 Page 2 of 23 CASE 0:15-cr-00247-PJS-SER Doc. 1 Filed 09/10/15 Page 3 of 23 CASE 0:15-cr-00247-PJS-SER Doc. 1 Filed 09/10/15 Page 4 of 23 CASE 0:15-cr-00247-PJS-SER Doc. 1 Filed 09/10/15 Page 5 of 23 CASE 0:15-cr-00247-PJS-SER Doc. 1 Filed 09/10/15 Page 6 of 23 CASE 0:15-cr-00247-PJS-SER Doc. 1 Filed 09/10/15 Page 7 of 23 CASE 0:15-cr-00247-PJS-SER Doc. 1 Filed 09/10/15 Page 8 of 23 CASE 0:15-cr-00247-PJS-SER Doc. 1 Filed 09/10/15 Page 9 of 23 CASE 0:15-cr-00247-PJS-SER Doc. 1 Filed 09/10/15 Page 10 of 23 CASE 0:15-cr-00247-PJS-SER Doc. 1 Filed 09/10/15 Page 11 of 23 CASE 0:15-cr-00247-PJS-SER Doc. 1 Filed 09/10/15 Page 12 of 23 CASE 0:15-cr-00247-PJS-SER Doc. 1 Filed 09/10/15 Page 13 of 23 CASE 0:15-cr-00247-PJS-SER Doc. 1 Filed 09/10/15 Page 14 of 23 CASE 0:15-cr-00247-PJS-SER Doc. 1 Filed 09/10/15 Page 15 of 23 CASE 0:15-cr-00247-PJS-SER Doc. 1 Filed 09/10/15 Page 16 of 23 CASE 0:15-cr-00247-PJS-SER Doc. 1 Filed 09/10/15 Page 17 of 23 CASE 0:15-cr-00247-PJS-SER Doc. 1 Filed 09/10/15 Page 18 of 23 CASE 0:15-cr-00247-PJS-SER Doc. 1 Filed 09/10/15 Page 19 of 23 CASE 0:15-cr-00247-PJS-SER Doc. 1 Filed 09/10/15 Page 20 of 23 | C105: ['https://assets.nationbuilder.com/cuapb/pages/1472/attachments/original/1669157534/Indictment_of_Jordan_Davis_15-CR-00247.pdf?1669157534'] | D105: ['Jordan Davis, badge #1434'] | E105: ['Department:Minneapolis Police Department'] | F105: 1392 | G105: TRUE | K105: =IF(Final_Cleaned_Data_V2!J105="Other", "Please specify here", "") | N105: =IF(Final_Cleaned_Data_V2!M105="Other", "Please specify here", "")
A106: 185 | B106: Fa  Election Results Weather Sports A Minnesota man was sentenced to 36 months in prison Friday for sexually assaulting and stalking a teenager while working as a police o Joshua Demmerly, 30, was charged in with sexually assault and stalking a teenager as an officer with the Warroad Police Department in A According to court documents, the victim claimed Demmerly told them that they were under investigation and the only way to get out of warrant was to spend time with him. Demmerly also allegedly gave the victim and other teens alcohol and tracked the victim's location via phone. The crimes were reported to take place when the victim was 16 and 17 years old. Demmerly pleaded guilty to two counts of criminal sexual conduct and two counts of stalking in September, according to court documen entering an Alford plea, a guilty plea in which the defendant still asserts innocence. He was sentenced on these counts Friday. He will serve a total of 36 months in the Minnesota Department of Corrections - St. Cloud. He for 221 days served. Most Read Ex-officer sentenced for sexually assaulting, stalking teenager (KVLY) Published: Nov. 9, 2019 at 3:17 PM CST  UPDATE: 2 dead in Lisbon structure fire Ex-officer sentenced for sexually assaulting, stalking teenager https://www.valleynewslive.com/content/news/Ex-officer-sentenced-for-sexually-assaulting-stalking... 1 of 3 11/22/2022, 5:06 PM | C106: ['https://assets.nationbuilder.com/cuapb/pages/1472/attachments/original/1669158590/Ex-officer_sentenced_for_sexually_assaulting__stalking_teenager.pdf?1669158590'] | D106: ['Joshua Demmerly, badge #None'] | E106: ['Department:Warroad Police Department'] | F106: 1398 | K106: =IF(Final_Cleaned_Data_V2!J106="Other", "Please specify here", "") | N106: =IF(Final_Cleaned_Data_V2!M106="Other", "Please specify here", "")
A107: 186 | B107: City of Minneapolis Request for Committee Action To: Ways & Means Date: 9/8/2015 From: City Attorney's Office Prepared by: Kristin Sarff Presented by: Susan Segal File type: Action Subcategory: Settlement Subject: Settlement of a lawsuit by Louis Tate. Description: Approving the settlement of the lawsuit of Louis Tate by payment of $25,000.00 to Louis Tate and his attorneys from Fund/Org. 06900 1500100 145400, and authorize the City Attorney's Office to execute any documents necessary to effectuate settlement. Previous Actions: None Ward/Neighborhood/Address: Ward 9 Midtown Phillips Intersection of 14th Avenue South and 24th Street East Background/Analysis: Plaintiff alleges causes of action for excessive force, assault, and battery. The parties have negotiated a proposed settlement in the amount of $25,000.00, including all claims for damages, attorneys' fees and costs. The City Attorney's Office and MPD administration believe that the proposed settlement is in the best interests of the City and recommend approval by this Committee and the City Council. Financial Review: No additional appropriation required, amount included in current budget. ☐ Future budget impact anticipated. ☐ Approved by the Permanent Review Committee. ☐ Meets Small and Underutilized Business Program goals. Attachments: 1. None | C107: ['https://d3n8a8pro7vhmx.cloudfront.net/cuapb/pages/270/attachments/original/1615063804/2015LouisTate.pdf?1615063804'] | D107: ['Brian Anderson, badge #91', 'Steven Lecy, badge #4057', 'Tracy Gross, badge #4070'] | E107: ['Department:Minneapolis Police Department'] | F107: 1404 | K107: =IF(Final_Cleaned_Data_V2!J107="Other", "Please specify here", "") | N107: =IF(Final_Cleaned_Data_V2!M107="Other", "Please specify here", "")
A108: 187 | B108: Home >Legislative File 2021-00659 >RCA Legal Se lement: Workers' Compensa on claims of Jeffrey Kading (RCA-2021-00673) ORIGINATING DEPARTMENT Finance & Property Services To Commi ee(s) # Commi ee Name Mee ng Date 1 Policy & Government Oversight Commi ee Jun 16, 2021 LEAD STAFF: Emily Ann Colby PRESENTED BY: Emily Ann Colby Ac on Item(s) # File Type Subcategory Item Descrip on 1 Ac on Se lement Approving the Workers' Compensa on claims of Jeffrey Kading by payment of $125,000 to Jeffrey Kading and his a orney(s), Meuser Law Firm, and authorizing the City A orney's Office to execute any documents necessary to effectuate the se lement. Ward / Neighborhood / Address RCA-2021-00673 - Legal Settlement: Workers' Compensation claims of ... https://lims.minneapolismn.gov/RCA/8119 1 of 2 12/4/2021, 12:41 AM # Ward Neighborhood Address 1. Not Applicable Background Analysis Former Minneapolis employee sustained work-related injuries. The par es reached a tenta ve se lement by payment of $125,000 from fund 06930-1450100-789401-145400. Risk Management believes this se lement is in the best interests of the City and recommends approval by the Commi ee and the City Council. FISCAL NOTE • Legal Se lement: Workers' Compensa on claims of Jeffrey Kading - Fiscal Note RCA-2021-00673 - Legal Settlement: Workers' Compensation claims of ... https://lims.minneapolismn.gov/RCA/8119 2 of 2 12/4/2021, 12:41 AM | C108: ["https://d3n8a8pro7vhmx.cloudfront.net/cuapb/pages/1462/attachments/original/1638637590/RCA-2021-00673_-_Legal_Settlement_Workers'_Compensation_claims_of_Jeffrey_Kading.pdf?1638637590"] | D108: ['Jeff Kading, badge #3598'] | E108: ['Department:Minneapolis Police Department'] | F108: 1406 | K108: =IF(Final_Cleaned_Data_V2!J108="Other", "Please specify here", "") | N108: =IF(Final_Cleaned_Data_V2!M108="Other", "Please specify here", "")
A109: 188 | B109: Home >Legislative File 2021-00403 >RCA Legal Se lement: Workers' Compensa on claim of Tammy Werner (RCA-2021-00431) ORIGINATING DEPARTMENT Finance & Property Services To Commi ee(s) # Commi ee Name Mee ng Date 1 Policy & Government Oversight Commi ee Apr 14, 2021 LEAD STAFF: Emily Ann Colby PRESENTED BY: Emily Ann Colby Ac on Item(s) # File Type Subcategory Item Descrip on 1 Ac on Se lement Approving the Workers' Compensa on claim of Tammy Werner by payment of $95,000 to Ms. Werner and her a orneys Meuser Law Firm, and authorizing the City A orney's Office to execute any documents necessary to effectuate the se lement. Ward / Neighborhood / Address RCA-2021-00431 - Legal Settlement: Workers' Compensation claim of ... https://lims.minneapolismn.gov/RCA/7805 1 of 2 12/4/2021, 12:28 AM # Ward Neighborhood Address 1. Not Applicable Background Analysis Former police officer Tammy Werner sustained admi ed work-related injuries. The par es have reached a tenta ve se lement by payment of $95,000 from Fund 06930-1450100-789410-145400. Risk Management believes the se lement is in the best interests of the City and recommends approval by this Commi ee and the City Council. FISCAL NOTE • Legal Se lement: Workers' Compensa on claim of Tammy Werner - Fiscal Note RCA-2021-00431 - Legal Settlement: Workers' Compensation claim of ... https://lims.minneapolismn.gov/RCA/7805 2 of 2 12/4/2021, 12:28 AM | C109: ["https://d3n8a8pro7vhmx.cloudfront.net/cuapb/pages/1462/attachments/original/1638637585/RCA-2021-00431_-_Legal_Settlement_Workers'_Compensation_claim_of_Tammy_Werner.pdf?1638637585"] | D109: ['Tammy Werner, badge #2119'] | E109: ['Department:Minneapolis Police Department'] | F109: 1406 | K109: =IF(Final_Cleaned_Data_V2!J109="Other", "Please specify here", "") | N109: =IF(Final_Cleaned_Data_V2!M109="Other", "Please specify here", "")
A110: 189 | B110: Home >Legislative File 2021-00542 >RCA Legal Se lement: Workers' Compensa on claim of Gene Suker (RCA-2021-00545) ORIGINATING DEPARTMENT Finance & Property Services To Commi ee(s) # Commi ee Name Mee ng Date 1 Policy & Government Oversight Commi ee May 12, 2021 LEAD STAFF: Emily Ann Colby PRESENTED BY: Emily Ann Colby Ac on Item(s) # File Type Subcategory Item Descrip on 1 Ac on Se lement Approving the Workers' Compensa on claim of Gene Suker by payment of $200,000 over three years to Mr. Gene Suker and his a orney's Meuser Law Firm and authorizing the City A orney's Office to execute any documents necessary to effectuate the se lement. Ward / Neighborhood / Address RCA-2021-00545 - Legal Settlement: Workers' Compensation claim of ... https://lims.minneapolismn.gov/RCA/7955 1 of 2 12/4/2021, 12:31 AM # Ward Neighborhood Address 1. Not Applicable Background Analysis Former employee sustained work-related injuries. The par es reached a tenta ve se lement by payment of $200,000 over three years from fund 06930-1450100-789401-145400. Risk Management believes the se lement is in the best interrsts of the City and recommends approval by the Commi ee and the City Council. FISCAL NOTE • Legal Se lement: Workers' Compensa on claim of Gene Suker - Fiscal Note RCA-2021-00545 - Legal Settlement: Workers' Compensation claim of ... https://lims.minneapolismn.gov/RCA/7955 2 of 2 12/4/2021, 12:31 AM | C110: ["https://d3n8a8pro7vhmx.cloudfront.net/cuapb/pages/1462/attachments/original/1638637589/RCA-2021-00545_-_Legal_Settlement_Workers'_Compensation_claim_of_Gene_Suker.pdf?1638637589"] | D110: ['Gene Suker, badge #7004'] | E110: ['Department:Minneapolis Police Department'] | F110: 1407 | K110: =IF(Final_Cleaned_Data_V2!J110="Other", "Please specify here", "") | N110: =IF(Final_Cleaned_Data_V2!M110="Other", "Please specify here", "")
A111: 190 | B111: Home >Legislative File 2021-00544 >RCA Legal Se lement: Workers' Compensa on claim of David Robins (RCA-2021-00547) ORIGINATING DEPARTMENT Finance & Property Services To Commi ee(s) # Commi ee Name Mee ng Date 1 Policy & Government Oversight Commi ee May 12, 2021 LEAD STAFF: Emily Ann Colby PRESENTED BY: Emily Ann Colby Ac on Item(s) # File Type Subcategory Item Descrip on 1 Ac on Se lement Approving the Workers' Compensa on claim of David Robins by payment of $125,000 over two years to Mr. Robins and his a orneys Meuser Law Firm and authorizing the City A orney's Office to execute any documents necessary to effectuate the se lement. Ward / Neighborhood / Address RCA-2021-00547 - Legal Settlement: Workers' Compensation claim of ... https://lims.minneapolismn.gov/RCA/7957 1 of 2 12/4/2021, 12:35 AM # Ward Neighborhood Address 1. Not Applicable Background Analysis Former employee sustained work-related injuries. The par es reached a tenta ve se lement by payment of $125,000 over two years from fund 06930-1450100-789401-145400. Risk Management believes this se lement to be in the best interests of the City and recommends approval by the Commi ee and the City Council. FISCAL NOTE • Legal Se lement: Workers' Compensa on claim of David Robins - Fiscal Note RCA-2021-00547 - Legal Settlement: Workers' Compensation claim of ... https://lims.minneapolismn.gov/RCA/7957 2 of 2 12/4/2021, 12:35 AM | C111: ["https://d3n8a8pro7vhmx.cloudfront.net/cuapb/pages/1462/attachments/original/1638637590/RCA-2021-00547_-_Legal_Settlement_Workers'_Compensation_claim_of_David_Robins.pdf?1638637590"] | D111: ['David Robins, badge #6046'] | E111: ['Department:Minneapolis Police Department'] | F111: 1408 | K111: =IF(Final_Cleaned_Data_V2!J111="Other", "Please specify here", "") | N111: =IF(Final_Cleaned_Data_V2!M111="Other", "Please specify here", "")
A112: 191 | B112: Home >Legislative File 2021-01037 >RCA Legal se lement: Workers' Compensa on claim of James Burns (RCA-2021-01068) ORIGINATING DEPARTMENT Finance & Property Services To Commi ee(s) # Commi ee Name Mee ng Date 1 Policy & Government Oversight Commi ee Sep 22, 2021 LEAD STAFF: Emily Ann Colby PRESENTED BY: Emily Ann Colby Ac on Item(s) # File Type Subcategory Item Descrip on 1 Ac on Se lement Approving the se lement of the Workers' Compensa on claim of James Burns, by payment of $125,000 to James Burns and a orney, Meuser Law Firm, and authorizing the City A orney's Office to execute any documents necessary to effectuate the se lement. Previous Ac ons None RCA-2021-01068 - Legal settlement: Workers' Compensation claim of ... https://lims.minneapolismn.gov/RCA/8597 1 of 2 12/4/2021, 1:15 AM Ward / Neighborhood / Address # Ward Neighborhood Address 1. Not Applicable Background Analysis City employee sustained work-related injuries. The par es have reached a tenta ve se lement by payment of $125,000 from fund 06930-1450100-789401-145400. Risk Management believes the se lement is in the best interests of the City and recommends approval by the Commi ee and the City Council. FISCAL NOTE • Legal se lement: Workers' Compensa on claim of James Burns - Fiscal Note RCA-2021-01068 - Legal settlement: Workers' Compensation claim of ... https://lims.minneapolismn.gov/RCA/8597 2 of 2 12/4/2021, 1:15 AM | C112: ["https://d3n8a8pro7vhmx.cloudfront.net/cuapb/pages/1462/attachments/original/1638637598/RCA-2021-01068_-_Legal_settlement_Workers'_Compensation_claim_of_James_Burns.pdf?1638637598"] | D112: ['James L. Burns, badge #884'] | E112: ['Department:Minneapolis Police Department'] | F112: 1408 | K112: =IF(Final_Cleaned_Data_V2!J112="Other", "Please specify here", "") | N112: =IF(Final_Cleaned_Data_V2!M112="Other", "Please specify here", "")
A113: 192 | B113: STAR TRIBUNE › Annotations Off-duty McLeod County deputy, Norwood Young America man from April ್೓ shooting identified APRIL ೅ೇ, ೅ೃೄೈ The Department of Public Safety released the names Friday of an off-duty deputy sheriff and another man involved in the April  shooting at a Kwik Trip store in Norwood Young America. McLeod County Sheriff's Deputy Matthew Allen Wyatt, , stopped to refuel at the gas station at  Reform St. when a call about an unruly patron came in around : a.m. Wyatt struggled with the patron, Michael Thomas Montgomery, , of Norwood Young America, before a firearm discharged, according to Carver County Sheriff Jim Olson. Montgomery fled the scene before being apprehended a few blocks away. Both men were treated for noncritical injuries. It is still unclear who fired the weapon and whether either man will face criminal charges related to the incident. The Bureau of Criminal Apprehension is investigating Wyatt's use of force and will present its findings to the Carver County attorney's office for review, according to a news release. Annotations · Report a problem COPY https://outline.com/dw3edy ✕ HOME · TERMS · PRIVACY · DMCA · CONTACT Outline is a free service for reading and annotating news articles. We remove the clutter so you can analyze and comment on the content. In today's climate of widespread misinformation, Outline empowers readers to verify the facts. | C113: ['https://d3n8a8pro7vhmx.cloudfront.net/cuapb/pages/270/attachments/original/1627047812/Off-duty_McLeod_County_deputy__Norwood_Young_America_man_from_April_17_shooting_identified.pdf?1627047812'] | D113: ['Matthew A. Wyatt, badge #None', 'Michael Zeug, badge #None'] | E113: ['Department:', 'Department:McLeod County Sheriffs Office'] | F113: 1409 | K113: =IF(Final_Cleaned_Data_V2!J113="Other", "Please specify here", "") | N113: =IF(Final_Cleaned_Data_V2!M113="Other", "Please specify here", "")
A114: 193 | B114: Home >Legislative File 2021-00536 >RCA Legal Se lement: Workers' Compensa on claims of Luke Eckert (RCA-2021-00524) ORIGINATING DEPARTMENT Finance & Property Services To Commi ee(s) # Commi ee Name Mee ng Date 1 Policy & Government Oversight Commi ee May 12, 2021 LEAD STAFF: Emily Ann Colby PRESENTED BY: Emily Ann Colby Ac on Item(s) # File Type Subcategory Item Descrip on 1 Ac on Se lement Approving the Workers' Compensa on claims of Luke Eckert by payment of $175,000 over three years to Mr. Eckert and his a orneys Meuser Law Firm and authorizing the City A orney's Office to execute any documents necessary to effectuate the se lement. Ward / Neighborhood / Address RCA-2021-00524 - Legal Settlement: Workers' Compensation claims of... https://lims.minneapolismn.gov/RCA/7936 1 of 2 12/4/2021, 12:34 AM # Ward Neighborhood Address 1. Not Applicable Background Analysis Former MPD Officer sustained work-related injuries. The par es reached a tenta ve se lement by payment of $175,000 over three years from fund 06930-1450100-789401-145400. Risk Management believes the se lement is in the best interests of hte City and recommends approval by the Commi ee and the City Council. FISCAL NOTE • Legal Se lement: Workers' Compensa on claims of Luke Eckert - Fiscal Note RCA-2021-00524 - Legal Settlement: Workers' Compensation claims of... https://lims.minneapolismn.gov/RCA/7936 2 of 2 12/4/2021, 12:34 AM | C114: ["https://d3n8a8pro7vhmx.cloudfront.net/cuapb/pages/1462/attachments/original/1638637587/RCA-2021-00524_-_Legal_Settlement_Workers'_Compensation_claims_of_Luke_Eckert.pdf?1638637587"] | D114: ['Luke Eckert, badge #1715'] | E114: ['Department:Minneapolis Police Department'] | F114: 1411 | K114: =IF(Final_Cleaned_Data_V2!J114="Other", "Please specify here", "") | N114: =IF(Final_Cleaned_Data_V2!M114="Other", "Please specify here", "")
A115: 194 | B115: Home >Legislative File 2021-00661 >RCA Legal Se lement: Workers' Compensa on claim of Tracy Gross (RCA-2021-00682) ORIGINATING DEPARTMENT Finance & Property Services To Commi ee(s) # Commi ee Name Mee ng Date 1 Policy & Government Oversight Commi ee Jun 16, 2021 LEAD STAFF: Emily Ann Colby PRESENTED BY: Emily Ann Colby Ac on Item(s) # File Type Subcategory Item Descrip on 1 Ac on Se lement Approving the Workers' Compensa on claim of Tracy Gross by payment of $150,000 over three years to Ms. Gross and her a orney, Meuser Law Firm, and authorizing the City A orney's Office to execute any documents necessary to effectuate the se lement. Ward / Neighborhood / Address RCA-2021-00682 - Legal Settlement: Workers' Compensation claim of T... https://lims.minneapolismn.gov/RCA/7987 1 of 2 12/4/2021, 12:41 AM # Ward Neighborhood Address 1. Not Applicable Background Analysis Former Minneaplis employee sustained work-related injuries. The par es reached a tenta ve se lment by payment of $150,000 over 3 years from fund 06930-1450100-789401-145-400. Risk Management believes the se lement is in the best interests of the City and recommends aproval by the Commi ee and the City Counsel. FISCAL NOTE • Legal Se lement: Workers' Compensa on claim of Tracy Gross - Fiscal Note RCA-2021-00682 - Legal Settlement: Workers' Compensation claim of T... https://lims.minneapolismn.gov/RCA/7987 2 of 2 12/4/2021, 12:41 AM | C115: ["https://d3n8a8pro7vhmx.cloudfront.net/cuapb/pages/1462/attachments/original/1638637592/RCA-2021-00682_-_Legal_Settlement_Workers'_Compensation_claim_of_Tracy_Gross.pdf?1638637592"] | D115: ['Tracy Gross, badge #4070'] | E115: ['Department:Minneapolis Police Department'] | F115: 1413 | K115: =IF(Final_Cleaned_Data_V2!J115="Other", "Please specify here", "") | N115: =IF(Final_Cleaned_Data_V2!M115="Other", "Please specify here", "")
A116: 195 | B116: Home >Legislative File 2021-00860 >RCA Legal Se lement: Workers' Compensa on claim of Christopher Steward (RCA-2021-00892) ORIGINATING DEPARTMENT Finance & Property Services To Commi ee(s) # Commi ee Name Mee ng Date 1 Policy & Government Oversight Commi ee Aug 4, 2021 LEAD STAFF: Emily Ann Colby PRESENTED BY: Emily Ann Colby Ac on Item(s) # File Type Subcategory Item Descrip on 1 Ac on Se lement Approving the Workers' Compensa on claims of Christopher Steward by payment of $130,000 to Christopher Steward and his a orney Meuser Law Firm, and authorizing the City A orney's Office to execute any documents necessary to effectuate the se lement. Ward / Neighborhood / Address RCA-2021-00892 - Legal Settlement: Workers' Compensation claim of C... https://lims.minneapolismn.gov/RCA/8385 1 of 2 12/4/2021, 12:51 AM # Ward Neighborhood Address 1. All Wards Background Analysis City of Minneapolis employee sustained work-related injuries. The par es reached a tenta ve se lement by payment of $130,000 from fund 06930-1450100-789401-145400. Risk Management believes the se lement is in the best interests of the City and recommends approval by the Comi ee and the City Council. FISCAL NOTE • Legal Se lement: Workers' Compensa on claim of Christopher Steward - Fiscal Note RCA-2021-00892 - Legal Settlement: Workers' Compensation claim of C... https://lims.minneapolismn.gov/RCA/8385 2 of 2 12/4/2021, 12:51 AM | C116: ["https://d3n8a8pro7vhmx.cloudfront.net/cuapb/pages/1462/attachments/original/1638637593/RCA-2021-00892_-_Legal_Settlement_Workers'_Compensation_claim_of_Christopher_Steward.pdf?1638637593"] | D116: ['Christopher Steward, badge #6823'] | E116: ['Department:Minneapolis Police Department'] | F116: 1413 | K116: =IF(Final_Cleaned_Data_V2!J116="Other", "Please specify here", "") | N116: =IF(Final_Cleaned_Data_V2!M116="Other", "Please specify here", "")
A117: 196 | B117: Home >Legislative File 2021-00859 >RCA Legal Se lement: Workers' Compensa on claim of Mark Sauer (RCA-2021-00896) ORIGINATING DEPARTMENT Finance & Property Services To Commi ee(s) # Commi ee Name Mee ng Date 1 Policy & Government Oversight Commi ee Aug 4, 2021 LEAD STAFF: Emily Ann Colby PRESENTED BY: Emily Ann Colby Ac on Item(s) # File Type Subcategory Item Descrip on 1 Ac on Se lement Approving the Workers' Compensa on claim of Mark Sauer by payment of $160,000 over three years to Mark Sauer and his a orneys Meuser Law Firm, and authorizing the City A orney's Office to execute any documents necessary to effectuate the se lement. Ward / Neighborhood / Address RCA-2021-00896 - Legal Settlement: Workers' Compensation claim of ... https://lims.minneapolismn.gov/RCA/8392 1 of 2 12/4/2021, 12:49 AM # Ward Neighborhood Address 1. Not Applicable Background Analysis City of Minneapolis employee sustained work-related ijureis. The par es reached a tenta ve se lement by payment of $160,000 over three years from fund 06930-1450100-789401-145400. Risk Management believes the se lement is in the best interests of the City and Rrecommends approval by the Commi ee and the City Council. FISCAL NOTE • Legal Se lement: Workers' Compensa on claim of Mark Sauer - Fiscal Note RCA-2021-00896 - Legal Settlement: Workers' Compensation claim of ... https://lims.minneapolismn.gov/RCA/8392 2 of 2 12/4/2021, 12:49 AM | C117: ["https://d3n8a8pro7vhmx.cloudfront.net/cuapb/pages/1462/attachments/original/1638637593/RCA-2021-00896_-_Legal_Settlement_Workers'_Compensation_claim_of_Mark_Sauer.pdf?1638637593"] | D117: ['Mark J. Sauer, badge #6308'] | E117: ['Department:Minneapolis Police Department'] | F117: 1414 | K117: =IF(Final_Cleaned_Data_V2!J117="Other", "Please specify here", "") | N117: =IF(Final_Cleaned_Data_V2!M117="Other", "Please specify here", "")
... A173: 252 | B173: Hennepin County 300 South Sixth Street, Minneapolis, MN 55487 DATE: February 18, 2022 TO: Deputy Samuel Fox FROM: Professional Standards Division RE: Written Reprimand You are receiving a written reprimand for your failure to follow Hennepin County's COVID-19 Vaccination and Testing Policy. Hennepin County has sent regular and ongoing communication regarding the policy expectation of being fully vaccinated or complying with weekly COVID testing. During the week of January 16-22, 2022 you failed to provide proof: • Of your vaccination status, or • That you had taken a COVID test and provided your test results Due to the seriousness of your failure to follow directives and abide by the county's vaccination and testing policy, you are being issued this written reprimand. It is my hope that you will take advantage of this opportunity to correct your behavior so that you may succeed in this position. Please note that continued incidents of this nature or a similar nature may result in additional, more serious disciplinary action up to and including termination. If you wish to appeal this action, your rights and the procedures are contained in the Labor Agreement between Hennepin County and the Minnesota Public Employees Association. Cc: Manager HR Business Partner Labor Relations Representative Payroll Contact Employee HR File | C173: ['https://assets.nationbuilder.com/cuapb/pages/1473/attachments/original/1671254317/20220218_Fox.pdf?1671254317'] | D173: ['Samuel Fox, badge #578'] | E173: ["Department:Hennepin County Sheriff's Department"] | F173: 1446 | K173: =IF(Final_Cleaned_Data_V2!J173="Other", "Please specify here", "") | N173: =IF(Final_Cleaned_Data_V2!M173="Other", "Please specify here", "")
A174: 253 | B174: Too_Long:Over 20 PagesOPCR Case #16-01727 PANEL RECOMMENDATION Page 2 of 3 Allegations 1. It is alleged that Officer Cape did not use reasonable judgement when handling the shotgun leading to the accidental discharge. (MPD P&P 5-105) CUAPB000735 OPCR Case #16-01727 PANEL RECOMMENDATION Page 3 of 3 Allegation #1: It is alleged that Officer Cape did not use reasonable judgement when handling the shotgun leading to the accidental discharge. Supportive Findings: YES NO REMAND SPLIT This allegation has merit. This allegation does not have merit. Remand to investigation for additional information. There is no majority vote. CUAPB000736 The panel finds merit with this allegation. Officer Cape failed to ensure the shotgun was completely unloaded, which created an unsafe condition resulting in an accidental discharge. The improper check of the chamber of the shotgun violates City Policy which states,"Employees shall use reasonable judgment in carrying out their duties and responsibilities. They need to weigh the consequences of their actions." Officer Cape's actions were unreasonable. Had Officer Cape properly checked the chamber of his shotgun prior to pulling the trigger, the discharge would not have occurred. Officer Cape admits to making a mistake and has received training to help prevent this from occurring again. | C174: ['https://d3n8a8pro7vhmx.cloudfront.net/cuapb/pages/270/attachments/original/1581619794/OPCR_case_16-01727_Cape.pdf?1581619794'] | D174: ['Charles Cape, badge #971'] | E174: ['Department:Minneapolis Police Department'] | F174: 1446 | G174: TRUE | K174: =IF(Final_Cleaned_Data_V2!J174="Other", "Please specify here", "") | N174: =IF(Final_Cleaned_Data_V2!M174="Other", "Please specify here", "")
A175: 254 | B175: Home >Legislative File 2021-01140 >RCA Legal se lement: Workers' Compensa on claim of Alan Williams (RCA-2021-01198) ORIGINATING DEPARTMENT Finance & Property Services To Commi ee(s) # Commi ee Name Mee ng Date 1 Policy & Government Oversight Commi ee Oct 20, 2021 LEAD STAFF: Emily Ann Colby PRESENTED BY: Emily Ann Colby Ac on Item(s) # File Type Subcategory Item Descrip on 1 Ac on Se lement Approving the se lement of the Workers' Compensa on claim of Alan Williams, by payment of $172,500 to Alan Williams and a orney, Meuser Law Firm, and authorizing the City A orney's Office to execute any documents necessary to effectuate the se lement. Previous Ac ons None RCA-2021-01198 - Legal settlement: Workers' Compensation claim of A... https://lims.minneapolismn.gov/RCA/8747 1 of 2 12/4/2021, 1:47 AM Ward / Neighborhood / Address # Ward Neighborhood Address 1. Not Applicable Background Analysis City of Minneapolis employee sustained work-related injuries. The par es reached a tenta ve se lement by payment of $172,500 over three years from fund 06930-1450100-789401-145400. Risk Management believes this se lement is in the best interests of the City and recommends approval by the Commi ee and the City Council. FISCAL NOTE • Legal se lement: Workers' Compensa on claim of Alan Williams - Fiscal Note RCA-2021-01198 - Legal settlement: Workers' Compensation claim of A... https://lims.minneapolismn.gov/RCA/8747 2 of 2 12/4/2021, 1:47 AM | C175: ["https://d3n8a8pro7vhmx.cloudfront.net/cuapb/pages/1462/attachments/original/1638637607/RCA-2021-01198_-_Legal_settlement_Workers'_Compensation_claim_of_Alan_Williams.pdf?1638637607"] | D175: ['Alan W. Williams, badge #7763'] | E175: ['Department:Minneapolis Police Department'] | F175: 1446 | K175: =IF(Final_Cleaned_Data_V2!J175="Other", "Please specify here", "") | N175: =IF(Final_Cleaned_Data_V2!M175="Other", "Please specify here", "")
A176: 255 | B176: MPR NEWS › Annotations Police ID St. Louis man shot by officers FEBRUARY ೄೇ, ೅ೃೄೆ St. Paul police have identified the man who was fatally shot by officers Tuesday after he stabbed a police dog. Alden Anderson, , of St. Louis was being sought by law enforcement on suspicion of first-degree criminal sexual conduct. Officers from St Paul, the North Star Fugitive Task Force, the Ramsey County Sheriff's Office, and US Marshals were aiding in the search. A police K- named Kody found Anderson in the basement of a Summit-University home, and Anderson stabbed the dog to death. St. Paul police spokesman Paul Paulos said Officer Jeffrey Thissen fired his weapon and has been placed on standard administrative leave. Two US Marshals also fired their weapons. A spokesperson for the Marshals Service said it does not identify officers. Paulos said there are no plans to publicly memorialize K- officer Kody. "We do let the handlers do their own thing; we consider the dogs one of their family members, so it is a private matter," Paulos said. The last time a St. Paul police dog was killed was , he said. Annotations · Report a problem COPY https://outline.com/GPDNVn ✕ HOME · TERMS · PRIVACY · DMCA · CONTACT Outline is a free service for reading and annotating news articles. We remove the clutter so you can analyze and comment on the content. In today's climate of widespread misinformation, Outline empowers readers to verify the facts. | C176: ['https://d3n8a8pro7vhmx.cloudfront.net/cuapb/pages/270/attachments/original/1626490928/Police_ID_St._Louis_man_shot_by_officers.pdf?1626490928'] | D176: ['Jeffrey C. Thissen, badge #679500'] | E176: ['Department:St. Paul Police Department'] | F176: 1446 | K176: =IF(Final_Cleaned_Data_V2!J176="Other", "Please specify here", "") | N176: =IF(Final_Cleaned_Data_V2!M176="Other", "Please specify here", "")
A177: 256 | B177: Hennepin County 300 South Sixth Street, Minneapolis, MN 55487 DATE: April 1, 2022 TO: Deputy Vladimir Litvinov FROM: Professional Standards Division RE: Written Reprimand You are receiving a written reprimand for your failure to follow Hennepin County's COVID-19 Vaccination and Testing Policy. Hennepin County has sent regular and ongoing communication regarding the policy expectation of being fully vaccinated or complying with weekly COVID testing. During the week of March 6-12, 2022 you failed to provide proof: • Of your vaccination status, or • That you had taken a COVID test and provided your test results Due to the seriousness of your failure to follow directives and abide by the county's vaccination and testing policy, you are being issued this written reprimand. It is my hope that you will take advantage of this opportunity to correct your behavior so that you may succeed in this position. Please note that continued incidents of this nature or a similar nature may result in additional, more serious disciplinary action up to and including termination. If you wish to appeal this action, your rights and the procedures are contained in the Labor Agreement between Hennepin County and the Minnesota Public Employees Association. Cc: Manager HR Business Partner Labor Relations Representative Payroll Contact Employee HR File | C177: ['https://assets.nationbuilder.com/cuapb/pages/1473/attachments/original/1671254234/20220401_Litvinov.pdf?1671254234'] | D177: ['Vladimir Litvinov, badge #622'] | E177: ["Department:Hennepin County Sheriff's Department"] | F177: 1446 | K177: =IF(Final_Cleaned_Data_V2!J177="Other", "Please specify here", "") | N177: =IF(Final_Cleaned_Data_V2!M177="Other", "Please specify here", "")
A178: 257 | B178: Home >Legislative File 2021-01143 >RCA Legal se lement: Workers' Compensa on claim of Jeremy Foster (RCA-2021-01195) ORIGINATING DEPARTMENT Finance & Property Services To Commi ee(s) # Commi ee Name Mee ng Date 1 Policy & Government Oversight Commi ee Oct 20, 2021 LEAD STAFF: Emily Ann Colby PRESENTED BY: Emily Ann Colby Ac on Item(s) # File Type Subcategory Item Descrip on 1 Ac on Se lement Approving the se lement of the Workers' Compensa on claim of Jeremy Foster, by payment of $175,000 to Jeremy Foster and a orney, Meuser Law Firm, and authorizing the City A orney's Office to execute any documents necessary to effectuate the se lement. Previous Ac ons None RCA-2021-01195 - Legal settlement: Workers' Compensation claim of J... https://lims.minneapolismn.gov/RCA/8744 1 of 2 12/4/2021, 1:41 AM Ward / Neighborhood / Address # Ward Neighborhood Address 1. Not Applicable Background Analysis City of Minneapolis employee sustained work-related injuries. The par es have reached a tenta ve se lement by payment of $175,000 over two years from fund 06930-1450100-789401-145400. Risk Management believes the se lement is in the best interests of the City and recommends approval by the Commi ee and the City Council. FISCAL NOTE • Legal se lement: Workers' Compensa on claim of Jeremy Foster - Fiscal Note RCA-2021-01195 - Legal settlement: Workers' Compensation claim of J... https://lims.minneapolismn.gov/RCA/8744 2 of 2 12/4/2021, 1:41 AM | C178: ["https://d3n8a8pro7vhmx.cloudfront.net/cuapb/pages/1462/attachments/original/1638637606/RCA-2021-01195_-_Legal_settlement_Workers'_Compensation_claim_of_Jeremy_Foster.pdf?1638637606"] | D178: ['Jeremy Foster, badge #2076'] | E178: ['Department:Minneapolis Police Department'] | F178: 1448 | K178: =IF(Final_Cleaned_Data_V2!J178="Other", "Please specify here", "") | N178: =IF(Final_Cleaned_Data_V2!M178="Other", "Please specify here", "")
A179: 258 | B179: Hennepin County 300 South Sixth Street, Minneapolis, MN 55487 DATE: February 18, 2022 TO: Deputy Mikale Clark FROM: Professional Standards Division RE: Written Reprimand You are receiving a written reprimand for your failure to follow Hennepin County's COVID-19 Vaccination and Testing Policy. Hennepin County has sent regular and ongoing communication regarding the policy expectation of being fully vaccinated or complying with weekly COVID testing. During the week of January 23-29, 2022 you failed to provide proof: • Of your vaccination status, or • That you had taken a COVID test and provided your test results Due to the seriousness of your failure to follow directives and abide by the county's vaccination and testing policy, you are being issued this written reprimand. It is my hope that you will take advantage of this opportunity to correct your behavior so that you may succeed in this position. Please note that continued incidents of this nature or a similar nature may result in additional, more serious disciplinary action up to and including termination. If you wish to appeal this action, your rights and the procedures are contained in the Labor Agreement between Hennepin County and the Minnesota Public Employees Association. Cc: Manager HR Business Partner Labor Relations Representative Payroll Contact Employee HR File | C179: ['https://assets.nationbuilder.com/cuapb/pages/1473/attachments/original/1671254317/20220218_Clark.pdf?1671254317'] | D179: ['Mikale Clark, badge #672'] | E179: ["Department:Hennepin County Sheriff's Department"] | F179: 1448 | K179: =IF(Final_Cleaned_Data_V2!J179="Other", "Please specify here", "") | N179: =IF(Final_Cleaned_Data_V2!M179="Other", "Please specify here", "")
A180: 259 | B180: Home >Legislative File 2021-01032 >RCA Legal se lement: Workers' Compensa on claim of Sco Creighton (RCA-2021-01080) ORIGINATING DEPARTMENT Finance & Property Services To Commi ee(s) # Commi ee Name Mee ng Date 1 Policy & Government Oversight Commi ee Sep 22, 2021 LEAD STAFF: Emily Ann Colby PRESENTED BY: Emily Ann Colby Ac on Item(s) # File Type Subcategory Item Descrip on 1 Ac on Se lement Approving the se lement of the Workers' Compensa on claim of Sco Creighton, by payment of $190,000 over three years to Sco Creighton and a orney, Meuser Law Firm, and authorizing the City A orney's Office to execute any documents necessary to effectuate the se lement. Previous Ac ons RCA-2021-01080 - Legal settlement: Workers' Compensation claim of S... https://lims.minneapolismn.gov/RCA/8610 1 of 2 12/4/2021, 1:09 AM none Ward / Neighborhood / Address # Ward Neighborhood Address 1. Not Applicable Background Analysis City employee sustained work-related injuries. The par es reached a tenta ve se lement by payment of $190,000 over three years from fund 06930-1450100-789401-145400. Risk Management believes this se lement is in the best interests of the City and recommends approval by the Commi ee and City Council. FISCAL NOTE • Legal se lement: Workers' Compensa on claim of Sco Creighton - Fiscal Note RCA-2021-01080 - Legal settlement: Workers' Compensation claim of S... https://lims.minneapolismn.gov/RCA/8610 2 of 2 12/4/2021, 1:09 AM | C180: ["https://d3n8a8pro7vhmx.cloudfront.net/cuapb/pages/1462/attachments/original/1638637602/RCA-2021-01080_-_Legal_settlement_Workers'_Compensation_claim_of_Scott_Creighton.pdf?1638637602"] | D180: ['Scott Creighton, badge #1331'] | E180: ['Department:Minneapolis Police Department'] | F180: 1448 | K180: =IF(Final_Cleaned_Data_V2!J180="Other", "Please specify here", "") | N180: =IF(Final_Cleaned_Data_V2!M180="Other", "Please specify here", "")
A181: 260 | B181: Home >Legislative File 2021-01040 >RCA Legal se lement: Workers' Compensa on claim of Michael Manley (RCA-2021-01070) ORIGINATING DEPARTMENT Finance & Property Services To Commi ee(s) # Commi ee Name Mee ng Date 1 Policy & Government Oversight Commi ee Sep 22, 2021 LEAD STAFF: Emily Ann Colby PRESENTED BY: Emily Ann Colby Ac on Item(s) # File Type Subcategory Item Descrip on 1 Ac on Se lement Approving se lement of the Workers' Compensa on claim of Michael Manley, by payment of $165,000 over three years to Michael Manley and a orney, Meuser Law Firm, and authorizing the City A orney's Office to execute any documents necessary to effectuate the se lement. Previous Ac ons RCA-2021-01070 - Legal settlement: Workers' Compensation claim of ... https://lims.minneapolismn.gov/RCA/8599 1 of 2 12/4/2021, 1:21 AM None Ward / Neighborhood / Address # Ward Neighborhood Address 1. Not Applicable Background Analysis City employee sustained work-related injuries. The par es have reached a tenta ve se lement by payment of $165,000 over three years from fund 06930-1450100-789401-145400. Risk Management believes the se lement is in the best interests of the City and recommends approval by the Commi ee and the City Council FISCAL NOTE • Legal se lement: Workers' Compensa on claim of Michael Manley - Fiscal Note RCA-2021-01070 - Legal settlement: Workers' Compensation claim of ... https://lims.minneapolismn.gov/RCA/8599 2 of 2 12/4/2021, 1:21 AM | C181: ["https://d3n8a8pro7vhmx.cloudfront.net/cuapb/pages/1462/attachments/original/1638637599/RCA-2021-01070_-_Legal_settlement_Workers'_Compensation_claim_of_Michael_Manley.pdf?1638637599"] | D181: ['Michael Manley, badge #4385'] | E181: ['Department:Minneapolis Police Department'] | F181: 1449 | K181: =IF(Final_Cleaned_Data_V2!J181="Other", "Please specify here", "") | N181: =IF(Final_Cleaned_Data_V2!M181="Other", "Please specify here", "")
